[2019-09-30 10:47:22,536: INFO/MainProcess] beat: Starting...
[2019-09-30 10:47:23,661: INFO/MainProcess] Scheduler: Sending due task check_balance_and_writing_to_db (check_balance_and_writing_to_db)
[2019-09-30 10:48:01,148: INFO/MainProcess] Scheduler: Sending due task check_balance_and_writing_to_db (check_balance_and_writing_to_db)
[2019-09-30 10:49:00,000: INFO/MainProcess] Scheduler: Sending due task check_balance_and_writing_to_db (check_balance_and_writing_to_db)
[2019-09-30 10:50:00,046: INFO/MainProcess] Scheduler: Sending due task check_balance_and_writing_to_db (check_balance_and_writing_to_db)
[2019-09-30 10:51:00,056: INFO/MainProcess] Scheduler: Sending due task check_balance_and_writing_to_db (check_balance_and_writing_to_db)
[2019-10-01 11:10:40,339: WARNING/MainProcess] Traceback (most recent call last):
[2019-10-01 11:10:40,392: WARNING/MainProcess] File "c:\Python27\lib\logging\__init__.py", line 861, in emit
[2019-10-01 11:10:40,398: WARNING/MainProcess] msg = self.format(record)
[2019-10-01 11:10:40,401: WARNING/MainProcess] File "c:\Python27\lib\logging\__init__.py", line 734, in format
[2019-10-01 11:10:40,404: WARNING/MainProcess] return fmt.format(record)
[2019-10-01 11:10:40,407: WARNING/MainProcess] File "C:\Users\Marisha\AppData\Roaming\Python\Python27\site-packages\celery\utils\log.py", line 153, in format
[2019-10-01 11:10:40,411: WARNING/MainProcess] msg = logging.Formatter.format(self, record)
[2019-10-01 11:10:40,414: WARNING/MainProcess] File "c:\Python27\lib\logging\__init__.py", line 465, in format
[2019-10-01 11:10:40,417: WARNING/MainProcess] record.message = record.getMessage()
[2019-10-01 11:10:40,420: WARNING/MainProcess] File "c:\Python27\lib\logging\__init__.py", line 329, in getMessage
[2019-10-01 11:10:40,424: WARNING/MainProcess] msg = msg % self.args
[2019-10-01 11:10:40,427: WARNING/MainProcess] UnicodeDecodeError: 'ascii' codec can't decode byte 0xcf in position 14: ordinal not in range(128)
[2019-10-01 11:10:40,430: WARNING/MainProcess] Logged from file consumer.py, line 425
[2019-10-01 11:10:43,461: WARNING/MainProcess] Traceback (most recent call last):
[2019-10-01 11:10:43,463: WARNING/MainProcess] File "c:\Python27\lib\logging\__init__.py", line 861, in emit
[2019-10-01 11:10:43,466: WARNING/MainProcess] msg = self.format(record)
[2019-10-01 11:10:43,469: WARNING/MainProcess] File "c:\Python27\lib\logging\__init__.py", line 734, in format
[2019-10-01 11:10:43,473: WARNING/MainProcess] return fmt.format(record)
[2019-10-01 11:10:43,476: WARNING/MainProcess] File "C:\Users\Marisha\AppData\Roaming\Python\Python27\site-packages\celery\utils\log.py", line 153, in format
[2019-10-01 11:10:43,480: WARNING/MainProcess] msg = logging.Formatter.format(self, record)
[2019-10-01 11:10:43,484: WARNING/MainProcess] File "c:\Python27\lib\logging\__init__.py", line 465, in format
[2019-10-01 11:10:43,487: WARNING/MainProcess] record.message = record.getMessage()
[2019-10-01 11:10:43,490: WARNING/MainProcess] File "c:\Python27\lib\logging\__init__.py", line 329, in getMessage
[2019-10-01 11:10:43,493: WARNING/MainProcess] msg = msg % self.args
[2019-10-01 11:10:43,496: WARNING/MainProcess] UnicodeDecodeError: 'ascii' codec can't decode byte 0xcf in position 14: ordinal not in range(128)
[2019-10-01 11:10:43,500: WARNING/MainProcess] Logged from file consumer.py, line 425
[2019-10-01 11:10:48,528: WARNING/MainProcess] Traceback (most recent call last):
[2019-10-01 11:10:48,542: WARNING/MainProcess] File "c:\Python27\lib\logging\__init__.py", line 861, in emit
[2019-10-01 11:10:48,551: WARNING/MainProcess] msg = self.format(record)
[2019-10-01 11:10:48,551: WARNING/MainProcess] File "c:\Python27\lib\logging\__init__.py", line 734, in format
[2019-10-01 11:10:48,552: WARNING/MainProcess] return fmt.format(record)
[2019-10-01 11:10:48,553: WARNING/MainProcess] File "C:\Users\Marisha\AppData\Roaming\Python\Python27\site-packages\celery\utils\log.py", line 153, in format
[2019-10-01 11:10:48,555: WARNING/MainProcess] msg = logging.Formatter.format(self, record)
[2019-10-01 11:10:48,555: WARNING/MainProcess] File "c:\Python27\lib\logging\__init__.py", line 465, in format
[2019-10-01 11:10:48,555: WARNING/MainProcess] record.message = record.getMessage()
[2019-10-01 11:10:48,556: WARNING/MainProcess] File "c:\Python27\lib\logging\__init__.py", line 329, in getMessage
[2019-10-01 11:10:48,562: WARNING/MainProcess] msg = msg % self.args
[2019-10-01 11:10:48,562: WARNING/MainProcess] UnicodeDecodeError: 'ascii' codec can't decode byte 0xcf in position 14: ordinal not in range(128)
[2019-10-01 11:10:48,563: WARNING/MainProcess] Logged from file consumer.py, line 425
[2019-10-01 11:10:55,585: WARNING/MainProcess] Traceback (most recent call last):
[2019-10-01 11:10:55,586: WARNING/MainProcess] File "c:\Python27\lib\logging\__init__.py", line 861, in emit
[2019-10-01 11:10:55,589: WARNING/MainProcess] msg = self.format(record)
[2019-10-01 11:10:55,592: WARNING/MainProcess] File "c:\Python27\lib\logging\__init__.py", line 734, in format
[2019-10-01 11:10:55,595: WARNING/MainProcess] return fmt.format(record)
[2019-10-01 11:10:55,598: WARNING/MainProcess] File "C:\Users\Marisha\AppData\Roaming\Python\Python27\site-packages\celery\utils\log.py", line 153, in format
[2019-10-01 11:10:55,601: WARNING/MainProcess] msg = logging.Formatter.format(self, record)
[2019-10-01 11:10:55,604: WARNING/MainProcess] File "c:\Python27\lib\logging\__init__.py", line 465, in format
[2019-10-01 11:10:55,607: WARNING/MainProcess] record.message = record.getMessage()
[2019-10-01 11:10:55,611: WARNING/MainProcess] File "c:\Python27\lib\logging\__init__.py", line 329, in getMessage
[2019-10-01 11:10:55,615: WARNING/MainProcess] msg = msg % self.args
[2019-10-01 11:10:55,619: WARNING/MainProcess] UnicodeDecodeError: 'ascii' codec can't decode byte 0xcf in position 14: ordinal not in range(128)
[2019-10-01 11:10:55,628: WARNING/MainProcess] Logged from file consumer.py, line 425
[2019-10-01 11:11:04,664: WARNING/MainProcess] Traceback (most recent call last):
[2019-10-01 11:11:04,664: WARNING/MainProcess] File "c:\Python27\lib\logging\__init__.py", line 861, in emit
[2019-10-01 11:11:04,667: WARNING/MainProcess] msg = self.format(record)
[2019-10-01 11:11:04,670: WARNING/MainProcess] File "c:\Python27\lib\logging\__init__.py", line 734, in format
[2019-10-01 11:11:04,673: WARNING/MainProcess] return fmt.format(record)
[2019-10-01 11:11:04,676: WARNING/MainProcess] File "C:\Users\Marisha\AppData\Roaming\Python\Python27\site-packages\celery\utils\log.py", line 153, in format
[2019-10-01 11:11:04,678: WARNING/MainProcess] msg = logging.Formatter.format(self, record)
[2019-10-01 11:11:04,680: WARNING/MainProcess] File "c:\Python27\lib\logging\__init__.py", line 465, in format
[2019-10-01 11:11:04,688: WARNING/MainProcess] record.message = record.getMessage()
[2019-10-01 11:11:04,694: WARNING/MainProcess] File "c:\Python27\lib\logging\__init__.py", line 329, in getMessage
[2019-10-01 11:11:04,697: WARNING/MainProcess] msg = msg % self.args
[2019-10-01 11:11:04,701: WARNING/MainProcess] UnicodeDecodeError: 'ascii' codec can't decode byte 0xcf in position 14: ordinal not in range(128)
[2019-10-01 11:11:04,707: WARNING/MainProcess] Logged from file consumer.py, line 425
[2019-10-01 11:11:15,759: WARNING/MainProcess] Traceback (most recent call last):
[2019-10-01 11:11:15,759: WARNING/MainProcess] File "c:\Python27\lib\logging\__init__.py", line 861, in emit
[2019-10-01 11:11:15,763: WARNING/MainProcess] msg = self.format(record)
[2019-10-01 11:11:15,766: WARNING/MainProcess] File "c:\Python27\lib\logging\__init__.py", line 734, in format
[2019-10-01 11:11:15,769: WARNING/MainProcess] return fmt.format(record)
[2019-10-01 11:11:15,773: WARNING/MainProcess] File "C:\Users\Marisha\AppData\Roaming\Python\Python27\site-packages\celery\utils\log.py", line 153, in format
[2019-10-01 11:11:15,778: WARNING/MainProcess] msg = logging.Formatter.format(self, record)
[2019-10-01 11:11:15,782: WARNING/MainProcess] File "c:\Python27\lib\logging\__init__.py", line 465, in format
[2019-10-01 11:11:15,789: WARNING/MainProcess] record.message = record.getMessage()
[2019-10-01 11:11:15,792: WARNING/MainProcess] File "c:\Python27\lib\logging\__init__.py", line 329, in getMessage
[2019-10-01 11:11:15,799: WARNING/MainProcess] msg = msg % self.args
[2019-10-01 11:11:15,802: WARNING/MainProcess] UnicodeDecodeError: 'ascii' codec can't decode byte 0xcf in position 14: ordinal not in range(128)
[2019-10-01 11:11:15,805: WARNING/MainProcess] Logged from file consumer.py, line 425
[2019-10-01 11:11:29,046: WARNING/MainProcess] Traceback (most recent call last):
[2019-10-01 11:11:29,048: WARNING/MainProcess] File "c:\Python27\lib\logging\__init__.py", line 861, in emit
[2019-10-01 11:11:29,052: WARNING/MainProcess] msg = self.format(record)
[2019-10-01 11:11:29,055: WARNING/MainProcess] File "c:\Python27\lib\logging\__init__.py", line 734, in format
[2019-10-01 11:11:29,059: WARNING/MainProcess] return fmt.format(record)
[2019-10-01 11:11:29,062: WARNING/MainProcess] File "C:\Users\Marisha\AppData\Roaming\Python\Python27\site-packages\celery\utils\log.py", line 153, in format
[2019-10-01 11:11:29,065: WARNING/MainProcess] msg = logging.Formatter.format(self, record)
[2019-10-01 11:11:29,069: WARNING/MainProcess] File "c:\Python27\lib\logging\__init__.py", line 465, in format
[2019-10-01 11:11:29,073: WARNING/MainProcess] record.message = record.getMessage()
[2019-10-01 11:11:29,078: WARNING/MainProcess] File "c:\Python27\lib\logging\__init__.py", line 329, in getMessage
[2019-10-01 11:11:29,081: WARNING/MainProcess] msg = msg % self.args
[2019-10-01 11:11:29,084: WARNING/MainProcess] UnicodeDecodeError: 'ascii' codec can't decode byte 0xcf in position 14: ordinal not in range(128)
[2019-10-01 11:11:29,086: WARNING/MainProcess] Logged from file consumer.py, line 425
[2019-10-01 11:11:44,515: WARNING/MainProcess] Traceback (most recent call last):
[2019-10-01 11:11:44,516: WARNING/MainProcess] File "c:\Python27\lib\logging\__init__.py", line 861, in emit
[2019-10-01 11:11:44,516: WARNING/MainProcess] msg = self.format(record)
[2019-10-01 11:11:44,516: WARNING/MainProcess] File "c:\Python27\lib\logging\__init__.py", line 734, in format
[2019-10-01 11:11:44,517: WARNING/MainProcess] return fmt.format(record)
[2019-10-01 11:11:44,519: WARNING/MainProcess] File "C:\Users\Marisha\AppData\Roaming\Python\Python27\site-packages\celery\utils\log.py", line 153, in format
[2019-10-01 11:11:44,519: WARNING/MainProcess] msg = logging.Formatter.format(self, record)
[2019-10-01 11:11:44,520: WARNING/MainProcess] File "c:\Python27\lib\logging\__init__.py", line 465, in format
[2019-10-01 11:11:44,520: WARNING/MainProcess] record.message = record.getMessage()
[2019-10-01 11:11:44,522: WARNING/MainProcess] File "c:\Python27\lib\logging\__init__.py", line 329, in getMessage
[2019-10-01 11:11:44,523: WARNING/MainProcess] msg = msg % self.args
[2019-10-01 11:11:44,523: WARNING/MainProcess] UnicodeDecodeError: 'ascii' codec can't decode byte 0xcf in position 14: ordinal not in range(128)
[2019-10-01 11:11:44,525: WARNING/MainProcess] Logged from file consumer.py, line 425
[2019-10-01 11:12:01,657: WARNING/MainProcess] Traceback (most recent call last):
[2019-10-01 11:12:01,657: WARNING/MainProcess] File "c:\Python27\lib\logging\__init__.py", line 861, in emit
[2019-10-01 11:12:01,661: WARNING/MainProcess] msg = self.format(record)
[2019-10-01 11:12:01,664: WARNING/MainProcess] File "c:\Python27\lib\logging\__init__.py", line 734, in format
[2019-10-01 11:12:01,667: WARNING/MainProcess] return fmt.format(record)
[2019-10-01 11:12:01,670: WARNING/MainProcess] File "C:\Users\Marisha\AppData\Roaming\Python\Python27\site-packages\celery\utils\log.py", line 153, in format
[2019-10-01 11:12:01,674: WARNING/MainProcess] msg = logging.Formatter.format(self, record)
[2019-10-01 11:12:01,680: WARNING/MainProcess] File "c:\Python27\lib\logging\__init__.py", line 465, in format
[2019-10-01 11:12:01,686: WARNING/MainProcess] record.message = record.getMessage()
[2019-10-01 11:12:01,690: WARNING/MainProcess] File "c:\Python27\lib\logging\__init__.py", line 329, in getMessage
[2019-10-01 11:12:01,694: WARNING/MainProcess] msg = msg % self.args
[2019-10-01 11:12:01,698: WARNING/MainProcess] UnicodeDecodeError: 'ascii' codec can't decode byte 0xcf in position 14: ordinal not in range(128)
[2019-10-01 11:12:01,703: WARNING/MainProcess] Logged from file consumer.py, line 425
[2019-10-01 11:12:20,969: WARNING/MainProcess] Traceback (most recent call last):
[2019-10-01 11:12:20,970: WARNING/MainProcess] File "c:\Python27\lib\logging\__init__.py", line 861, in emit
[2019-10-01 11:12:20,976: WARNING/MainProcess] msg = self.format(record)
[2019-10-01 11:12:20,996: WARNING/MainProcess] File "c:\Python27\lib\logging\__init__.py", line 734, in format
[2019-10-01 11:12:21,002: WARNING/MainProcess] return fmt.format(record)
[2019-10-01 11:12:21,006: WARNING/MainProcess] File "C:\Users\Marisha\AppData\Roaming\Python\Python27\site-packages\celery\utils\log.py", line 153, in format
[2019-10-01 11:12:21,010: WARNING/MainProcess] msg = logging.Formatter.format(self, record)
[2019-10-01 11:12:21,019: WARNING/MainProcess] File "c:\Python27\lib\logging\__init__.py", line 465, in format
[2019-10-01 11:12:21,026: WARNING/MainProcess] record.message = record.getMessage()
[2019-10-01 11:12:21,029: WARNING/MainProcess] File "c:\Python27\lib\logging\__init__.py", line 329, in getMessage
[2019-10-01 11:12:21,033: WARNING/MainProcess] msg = msg % self.args
[2019-10-01 11:12:21,036: WARNING/MainProcess] UnicodeDecodeError: 'ascii' codec can't decode byte 0xcf in position 14: ordinal not in range(128)
[2019-10-01 11:12:21,039: WARNING/MainProcess] Logged from file consumer.py, line 425
[2019-10-01 11:12:42,209: WARNING/MainProcess] Traceback (most recent call last):
[2019-10-01 11:12:42,210: WARNING/MainProcess] File "c:\Python27\lib\logging\__init__.py", line 861, in emit
[2019-10-01 11:12:42,213: WARNING/MainProcess] msg = self.format(record)
[2019-10-01 11:12:42,216: WARNING/MainProcess] File "c:\Python27\lib\logging\__init__.py", line 734, in format
[2019-10-01 11:12:42,219: WARNING/MainProcess] return fmt.format(record)
[2019-10-01 11:12:42,221: WARNING/MainProcess] File "C:\Users\Marisha\AppData\Roaming\Python\Python27\site-packages\celery\utils\log.py", line 153, in format
[2019-10-01 11:12:42,224: WARNING/MainProcess] msg = logging.Formatter.format(self, record)
[2019-10-01 11:12:42,227: WARNING/MainProcess] File "c:\Python27\lib\logging\__init__.py", line 465, in format
[2019-10-01 11:12:42,230: WARNING/MainProcess] record.message = record.getMessage()
[2019-10-01 11:12:42,233: WARNING/MainProcess] File "c:\Python27\lib\logging\__init__.py", line 329, in getMessage
[2019-10-01 11:12:42,236: WARNING/MainProcess] msg = msg % self.args
[2019-10-01 11:12:42,240: WARNING/MainProcess] UnicodeDecodeError: 'ascii' codec can't decode byte 0xcf in position 14: ordinal not in range(128)
[2019-10-01 11:12:42,243: WARNING/MainProcess] Logged from file consumer.py, line 425
[2019-10-01 11:13:15,365: WARNING/MainProcess] Traceback (most recent call last):
[2019-10-01 11:13:15,367: WARNING/MainProcess] File "c:\Python27\lib\logging\__init__.py", line 861, in emit
[2019-10-01 11:13:15,371: WARNING/MainProcess] msg = self.format(record)
[2019-10-01 11:13:15,374: WARNING/MainProcess] File "c:\Python27\lib\logging\__init__.py", line 734, in format
[2019-10-01 11:13:15,378: WARNING/MainProcess] return fmt.format(record)
[2019-10-01 11:13:15,381: WARNING/MainProcess] File "C:\Users\Marisha\AppData\Roaming\Python\Python27\site-packages\celery\utils\log.py", line 153, in format
[2019-10-01 11:13:15,384: WARNING/MainProcess] msg = logging.Formatter.format(self, record)
[2019-10-01 11:13:15,388: WARNING/MainProcess] File "c:\Python27\lib\logging\__init__.py", line 465, in format
[2019-10-01 11:13:15,391: WARNING/MainProcess] record.message = record.getMessage()
[2019-10-01 11:13:15,394: WARNING/MainProcess] File "c:\Python27\lib\logging\__init__.py", line 329, in getMessage
[2019-10-01 11:13:15,398: WARNING/MainProcess] msg = msg % self.args
[2019-10-01 11:13:15,401: WARNING/MainProcess] UnicodeDecodeError: 'ascii' codec can't decode byte 0xcf in position 14: ordinal not in range(128)
[2019-10-01 11:13:15,404: WARNING/MainProcess] Logged from file consumer.py, line 425
[2019-10-01 11:13:18,434: WARNING/MainProcess] Traceback (most recent call last):
[2019-10-01 11:13:18,434: WARNING/MainProcess] File "c:\Python27\lib\logging\__init__.py", line 861, in emit
[2019-10-01 11:13:18,436: WARNING/MainProcess] msg = self.format(record)
[2019-10-01 11:13:18,436: WARNING/MainProcess] File "c:\Python27\lib\logging\__init__.py", line 734, in format
[2019-10-01 11:13:18,437: WARNING/MainProcess] return fmt.format(record)
[2019-10-01 11:13:18,437: WARNING/MainProcess] File "C:\Users\Marisha\AppData\Roaming\Python\Python27\site-packages\celery\utils\log.py", line 153, in format
[2019-10-01 11:13:18,438: WARNING/MainProcess] msg = logging.Formatter.format(self, record)
[2019-10-01 11:13:18,440: WARNING/MainProcess] File "c:\Python27\lib\logging\__init__.py", line 465, in format
[2019-10-01 11:13:18,440: WARNING/MainProcess] record.message = record.getMessage()
[2019-10-01 11:13:18,441: WARNING/MainProcess] File "c:\Python27\lib\logging\__init__.py", line 329, in getMessage
[2019-10-01 11:13:18,443: WARNING/MainProcess] msg = msg % self.args
[2019-10-01 11:13:18,444: WARNING/MainProcess] UnicodeDecodeError: 'ascii' codec can't decode byte 0xcf in position 14: ordinal not in range(128)
[2019-10-01 11:13:18,444: WARNING/MainProcess] Logged from file consumer.py, line 425
[2019-10-01 11:13:23,464: WARNING/MainProcess] Traceback (most recent call last):
[2019-10-01 11:13:23,466: WARNING/MainProcess] File "c:\Python27\lib\logging\__init__.py", line 861, in emit
[2019-10-01 11:13:23,469: WARNING/MainProcess] msg = self.format(record)
[2019-10-01 11:13:23,473: WARNING/MainProcess] File "c:\Python27\lib\logging\__init__.py", line 734, in format
[2019-10-01 11:13:23,476: WARNING/MainProcess] return fmt.format(record)
[2019-10-01 11:13:23,479: WARNING/MainProcess] File "C:\Users\Marisha\AppData\Roaming\Python\Python27\site-packages\celery\utils\log.py", line 153, in format
[2019-10-01 11:13:23,482: WARNING/MainProcess] msg = logging.Formatter.format(self, record)
[2019-10-01 11:13:23,484: WARNING/MainProcess] File "c:\Python27\lib\logging\__init__.py", line 465, in format
[2019-10-01 11:13:23,490: WARNING/MainProcess] record.message = record.getMessage()
[2019-10-01 11:13:23,493: WARNING/MainProcess] File "c:\Python27\lib\logging\__init__.py", line 329, in getMessage
[2019-10-01 11:13:23,497: WARNING/MainProcess] msg = msg % self.args
[2019-10-01 11:13:23,502: WARNING/MainProcess] UnicodeDecodeError: 'ascii' codec can't decode byte 0xcf in position 14: ordinal not in range(128)
[2019-10-01 11:13:23,506: WARNING/MainProcess] Logged from file consumer.py, line 425
[2019-10-01 11:13:30,539: WARNING/MainProcess] Traceback (most recent call last):
[2019-10-01 11:13:30,539: WARNING/MainProcess] File "c:\Python27\lib\logging\__init__.py", line 861, in emit
[2019-10-01 11:13:30,543: WARNING/MainProcess] msg = self.format(record)
[2019-10-01 11:13:30,546: WARNING/MainProcess] File "c:\Python27\lib\logging\__init__.py", line 734, in format
[2019-10-01 11:13:30,549: WARNING/MainProcess] return fmt.format(record)
[2019-10-01 11:13:30,552: WARNING/MainProcess] File "C:\Users\Marisha\AppData\Roaming\Python\Python27\site-packages\celery\utils\log.py", line 153, in format
[2019-10-01 11:13:30,556: WARNING/MainProcess] msg = logging.Formatter.format(self, record)
[2019-10-01 11:13:30,559: WARNING/MainProcess] File "c:\Python27\lib\logging\__init__.py", line 465, in format
[2019-10-01 11:13:30,563: WARNING/MainProcess] record.message = record.getMessage()
[2019-10-01 11:13:30,566: WARNING/MainProcess] File "c:\Python27\lib\logging\__init__.py", line 329, in getMessage
[2019-10-01 11:13:30,571: WARNING/MainProcess] msg = msg % self.args
[2019-10-01 11:13:30,572: WARNING/MainProcess] UnicodeDecodeError: 'ascii' codec can't decode byte 0xcf in position 14: ordinal not in range(128)
[2019-10-01 11:13:30,576: WARNING/MainProcess] Logged from file consumer.py, line 425
[2019-10-01 11:13:39,599: WARNING/MainProcess] Traceback (most recent call last):
[2019-10-01 11:13:39,601: WARNING/MainProcess] File "c:\Python27\lib\logging\__init__.py", line 861, in emit
[2019-10-01 11:13:39,604: WARNING/MainProcess] msg = self.format(record)
[2019-10-01 11:13:39,608: WARNING/MainProcess] File "c:\Python27\lib\logging\__init__.py", line 734, in format
[2019-10-01 11:13:39,611: WARNING/MainProcess] return fmt.format(record)
[2019-10-01 11:13:39,615: WARNING/MainProcess] File "C:\Users\Marisha\AppData\Roaming\Python\Python27\site-packages\celery\utils\log.py", line 153, in format
[2019-10-01 11:13:39,618: WARNING/MainProcess] msg = logging.Formatter.format(self, record)
[2019-10-01 11:13:39,624: WARNING/MainProcess] File "c:\Python27\lib\logging\__init__.py", line 465, in format
[2019-10-01 11:13:39,628: WARNING/MainProcess] record.message = record.getMessage()
[2019-10-01 11:13:39,634: WARNING/MainProcess] File "c:\Python27\lib\logging\__init__.py", line 329, in getMessage
[2019-10-01 11:13:39,638: WARNING/MainProcess] msg = msg % self.args
[2019-10-01 11:13:39,641: WARNING/MainProcess] UnicodeDecodeError: 'ascii' codec can't decode byte 0xcf in position 14: ordinal not in range(128)
[2019-10-01 11:13:39,647: WARNING/MainProcess] Logged from file consumer.py, line 425
[2019-10-01 11:13:50,707: WARNING/MainProcess] Traceback (most recent call last):
[2019-10-01 11:13:50,707: WARNING/MainProcess] File "c:\Python27\lib\logging\__init__.py", line 861, in emit
[2019-10-01 11:13:50,710: WARNING/MainProcess] msg = self.format(record)
[2019-10-01 11:13:50,714: WARNING/MainProcess] File "c:\Python27\lib\logging\__init__.py", line 734, in format
[2019-10-01 11:13:50,719: WARNING/MainProcess] return fmt.format(record)
[2019-10-01 11:13:50,721: WARNING/MainProcess] File "C:\Users\Marisha\AppData\Roaming\Python\Python27\site-packages\celery\utils\log.py", line 153, in format
[2019-10-01 11:13:50,724: WARNING/MainProcess] msg = logging.Formatter.format(self, record)
[2019-10-01 11:13:50,727: WARNING/MainProcess] File "c:\Python27\lib\logging\__init__.py", line 465, in format
[2019-10-01 11:13:50,730: WARNING/MainProcess] record.message = record.getMessage()
[2019-10-01 11:13:50,734: WARNING/MainProcess] File "c:\Python27\lib\logging\__init__.py", line 329, in getMessage
[2019-10-01 11:13:50,737: WARNING/MainProcess] msg = msg % self.args
[2019-10-01 11:13:50,740: WARNING/MainProcess] UnicodeDecodeError: 'ascii' codec can't decode byte 0xcf in position 14: ordinal not in range(128)
[2019-10-01 11:13:50,744: WARNING/MainProcess] Logged from file consumer.py, line 425
[2019-10-01 11:14:03,782: WARNING/MainProcess] Traceback (most recent call last):
[2019-10-01 11:14:03,783: WARNING/MainProcess] File "c:\Python27\lib\logging\__init__.py", line 861, in emit
[2019-10-01 11:14:03,786: WARNING/MainProcess] msg = self.format(record)
[2019-10-01 11:14:03,789: WARNING/MainProcess] File "c:\Python27\lib\logging\__init__.py", line 734, in format
[2019-10-01 11:14:03,792: WARNING/MainProcess] return fmt.format(record)
[2019-10-01 11:14:03,795: WARNING/MainProcess] File "C:\Users\Marisha\AppData\Roaming\Python\Python27\site-packages\celery\utils\log.py", line 153, in format
[2019-10-01 11:14:03,798: WARNING/MainProcess] msg = logging.Formatter.format(self, record)
[2019-10-01 11:14:03,801: WARNING/MainProcess] File "c:\Python27\lib\logging\__init__.py", line 465, in format
[2019-10-01 11:14:03,803: WARNING/MainProcess] record.message = record.getMessage()
[2019-10-01 11:14:03,806: WARNING/MainProcess] File "c:\Python27\lib\logging\__init__.py", line 329, in getMessage
[2019-10-01 11:14:03,809: WARNING/MainProcess] msg = msg % self.args
[2019-10-01 11:14:03,812: WARNING/MainProcess] UnicodeDecodeError: 'ascii' codec can't decode byte 0xcf in position 14: ordinal not in range(128)
[2019-10-01 11:14:03,815: WARNING/MainProcess] Logged from file consumer.py, line 425
[2019-10-01 11:14:18,983: WARNING/MainProcess] Traceback (most recent call last):
[2019-10-01 11:14:18,983: WARNING/MainProcess] File "c:\Python27\lib\logging\__init__.py", line 861, in emit
[2019-10-01 11:14:18,984: WARNING/MainProcess] msg = self.format(record)
[2019-10-01 11:14:18,986: WARNING/MainProcess] File "c:\Python27\lib\logging\__init__.py", line 734, in format
[2019-10-01 11:14:18,986: WARNING/MainProcess] return fmt.format(record)
[2019-10-01 11:14:18,987: WARNING/MainProcess] File "C:\Users\Marisha\AppData\Roaming\Python\Python27\site-packages\celery\utils\log.py", line 153, in format
[2019-10-01 11:14:18,989: WARNING/MainProcess] msg = logging.Formatter.format(self, record)
[2019-10-01 11:14:18,990: WARNING/MainProcess] File "c:\Python27\lib\logging\__init__.py", line 465, in format
[2019-10-01 11:14:18,990: WARNING/MainProcess] record.message = record.getMessage()
[2019-10-01 11:14:18,992: WARNING/MainProcess] File "c:\Python27\lib\logging\__init__.py", line 329, in getMessage
[2019-10-01 11:14:18,993: WARNING/MainProcess] msg = msg % self.args
[2019-10-01 11:14:18,996: WARNING/MainProcess] UnicodeDecodeError: 'ascii' codec can't decode byte 0xcf in position 14: ordinal not in range(128)
[2019-10-01 11:14:19,000: WARNING/MainProcess] Logged from file consumer.py, line 425
[2019-10-01 11:14:36,035: WARNING/MainProcess] Traceback (most recent call last):
[2019-10-01 11:14:36,036: WARNING/MainProcess] File "c:\Python27\lib\logging\__init__.py", line 861, in emit
[2019-10-01 11:14:36,039: WARNING/MainProcess] msg = self.format(record)
[2019-10-01 11:14:36,042: WARNING/MainProcess] File "c:\Python27\lib\logging\__init__.py", line 734, in format
[2019-10-01 11:14:36,045: WARNING/MainProcess] return fmt.format(record)
[2019-10-01 11:14:36,049: WARNING/MainProcess] File "C:\Users\Marisha\AppData\Roaming\Python\Python27\site-packages\celery\utils\log.py", line 153, in format
[2019-10-01 11:14:36,052: WARNING/MainProcess] msg = logging.Formatter.format(self, record)
[2019-10-01 11:14:36,056: WARNING/MainProcess] File "c:\Python27\lib\logging\__init__.py", line 465, in format
[2019-10-01 11:14:36,062: WARNING/MainProcess] record.message = record.getMessage()
[2019-10-01 11:14:36,066: WARNING/MainProcess] File "c:\Python27\lib\logging\__init__.py", line 329, in getMessage
[2019-10-01 11:14:36,072: WARNING/MainProcess] msg = msg % self.args
[2019-10-01 11:14:36,076: WARNING/MainProcess] UnicodeDecodeError: 'ascii' codec can't decode byte 0xcf in position 14: ordinal not in range(128)
[2019-10-01 11:14:36,079: WARNING/MainProcess] Logged from file consumer.py, line 425
[2019-10-01 11:14:55,328: WARNING/MainProcess] Traceback (most recent call last):
[2019-10-01 11:14:55,329: WARNING/MainProcess] File "c:\Python27\lib\logging\__init__.py", line 861, in emit
[2019-10-01 11:14:55,332: WARNING/MainProcess] msg = self.format(record)
[2019-10-01 11:14:55,335: WARNING/MainProcess] File "c:\Python27\lib\logging\__init__.py", line 734, in format
[2019-10-01 11:14:55,338: WARNING/MainProcess] return fmt.format(record)
[2019-10-01 11:14:55,342: WARNING/MainProcess] File "C:\Users\Marisha\AppData\Roaming\Python\Python27\site-packages\celery\utils\log.py", line 153, in format
[2019-10-01 11:14:55,345: WARNING/MainProcess] msg = logging.Formatter.format(self, record)
[2019-10-01 11:14:55,348: WARNING/MainProcess] File "c:\Python27\lib\logging\__init__.py", line 465, in format
[2019-10-01 11:14:55,351: WARNING/MainProcess] record.message = record.getMessage()
[2019-10-01 11:14:55,354: WARNING/MainProcess] File "c:\Python27\lib\logging\__init__.py", line 329, in getMessage
[2019-10-01 11:14:55,355: WARNING/MainProcess] msg = msg % self.args
[2019-10-01 11:14:55,359: WARNING/MainProcess] UnicodeDecodeError: 'ascii' codec can't decode byte 0xcf in position 14: ordinal not in range(128)
[2019-10-01 11:14:55,362: WARNING/MainProcess] Logged from file consumer.py, line 425
[2019-10-01 11:15:16,444: WARNING/MainProcess] Traceback (most recent call last):
[2019-10-01 11:15:16,444: WARNING/MainProcess] File "c:\Python27\lib\logging\__init__.py", line 861, in emit
[2019-10-01 11:15:16,448: WARNING/MainProcess] msg = self.format(record)
[2019-10-01 11:15:16,450: WARNING/MainProcess] File "c:\Python27\lib\logging\__init__.py", line 734, in format
[2019-10-01 11:15:16,450: WARNING/MainProcess] return fmt.format(record)
[2019-10-01 11:15:16,451: WARNING/MainProcess] File "C:\Users\Marisha\AppData\Roaming\Python\Python27\site-packages\celery\utils\log.py", line 153, in format
[2019-10-01 11:15:16,453: WARNING/MainProcess] msg = logging.Formatter.format(self, record)
[2019-10-01 11:15:16,457: WARNING/MainProcess] File "c:\Python27\lib\logging\__init__.py", line 465, in format
[2019-10-01 11:15:16,460: WARNING/MainProcess] record.message = record.getMessage()
[2019-10-01 11:15:16,466: WARNING/MainProcess] File "c:\Python27\lib\logging\__init__.py", line 329, in getMessage
[2019-10-01 11:15:16,467: WARNING/MainProcess] msg = msg % self.args
[2019-10-01 11:15:16,470: WARNING/MainProcess] UnicodeDecodeError: 'ascii' codec can't decode byte 0xcf in position 14: ordinal not in range(128)
[2019-10-01 11:15:16,473: WARNING/MainProcess] Logged from file consumer.py, line 425
[2019-10-01 11:15:39,914: WARNING/MainProcess] Traceback (most recent call last):
[2019-10-01 11:15:39,914: WARNING/MainProcess] File "c:\Python27\lib\logging\__init__.py", line 861, in emit
[2019-10-01 11:15:39,915: WARNING/MainProcess] msg = self.format(record)
[2019-10-01 11:15:39,917: WARNING/MainProcess] File "c:\Python27\lib\logging\__init__.py", line 734, in format
[2019-10-01 11:15:39,917: WARNING/MainProcess] return fmt.format(record)
[2019-10-01 11:15:39,918: WARNING/MainProcess] File "C:\Users\Marisha\AppData\Roaming\Python\Python27\site-packages\celery\utils\log.py", line 153, in format
[2019-10-01 11:15:39,920: WARNING/MainProcess] msg = logging.Formatter.format(self, record)
[2019-10-01 11:15:39,921: WARNING/MainProcess] File "c:\Python27\lib\logging\__init__.py", line 465, in format
[2019-10-01 11:15:39,921: WARNING/MainProcess] record.message = record.getMessage()
[2019-10-01 11:15:39,924: WARNING/MainProcess] File "c:\Python27\lib\logging\__init__.py", line 329, in getMessage
[2019-10-01 11:15:39,927: WARNING/MainProcess] msg = msg % self.args
[2019-10-01 11:15:39,931: WARNING/MainProcess] UnicodeDecodeError: 'ascii' codec can't decode byte 0xcf in position 14: ordinal not in range(128)
[2019-10-01 11:15:39,933: WARNING/MainProcess] Logged from file consumer.py, line 425
[2019-10-01 11:16:05,099: WARNING/MainProcess] Traceback (most recent call last):
[2019-10-01 11:16:05,101: WARNING/MainProcess] File "c:\Python27\lib\logging\__init__.py", line 861, in emit
[2019-10-01 11:16:05,104: WARNING/MainProcess] msg = self.format(record)
[2019-10-01 11:16:05,107: WARNING/MainProcess] File "c:\Python27\lib\logging\__init__.py", line 734, in format
[2019-10-01 11:16:05,108: WARNING/MainProcess] return fmt.format(record)
[2019-10-01 11:16:05,108: WARNING/MainProcess] File "C:\Users\Marisha\AppData\Roaming\Python\Python27\site-packages\celery\utils\log.py", line 153, in format
[2019-10-01 11:16:05,109: WARNING/MainProcess] msg = logging.Formatter.format(self, record)
[2019-10-01 11:16:05,111: WARNING/MainProcess] File "c:\Python27\lib\logging\__init__.py", line 465, in format
[2019-10-01 11:16:05,111: WARNING/MainProcess] record.message = record.getMessage()
[2019-10-01 11:16:05,111: WARNING/MainProcess] File "c:\Python27\lib\logging\__init__.py", line 329, in getMessage
[2019-10-01 11:16:05,112: WARNING/MainProcess] msg = msg % self.args
[2019-10-01 11:16:05,114: WARNING/MainProcess] UnicodeDecodeError: 'ascii' codec can't decode byte 0xcf in position 14: ordinal not in range(128)
[2019-10-01 11:16:05,115: WARNING/MainProcess] Logged from file consumer.py, line 425
[2019-10-01 11:16:32,413: WARNING/MainProcess] Traceback (most recent call last):
[2019-10-01 11:16:32,414: WARNING/MainProcess] File "c:\Python27\lib\logging\__init__.py", line 861, in emit
[2019-10-01 11:16:32,414: WARNING/MainProcess] msg = self.format(record)
[2019-10-01 11:16:32,417: WARNING/MainProcess] File "c:\Python27\lib\logging\__init__.py", line 734, in format
[2019-10-01 11:16:32,417: WARNING/MainProcess] return fmt.format(record)
[2019-10-01 11:16:32,418: WARNING/MainProcess] File "C:\Users\Marisha\AppData\Roaming\Python\Python27\site-packages\celery\utils\log.py", line 153, in format
[2019-10-01 11:16:32,420: WARNING/MainProcess] msg = logging.Formatter.format(self, record)
[2019-10-01 11:16:32,421: WARNING/MainProcess] File "c:\Python27\lib\logging\__init__.py", line 465, in format
[2019-10-01 11:16:32,421: WARNING/MainProcess] record.message = record.getMessage()
[2019-10-01 11:16:32,426: WARNING/MainProcess] File "c:\Python27\lib\logging\__init__.py", line 329, in getMessage
[2019-10-01 11:16:32,434: WARNING/MainProcess] msg = msg % self.args
[2019-10-01 11:16:32,438: WARNING/MainProcess] UnicodeDecodeError: 'ascii' codec can't decode byte 0xcf in position 14: ordinal not in range(128)
[2019-10-01 11:16:32,443: WARNING/MainProcess] Logged from file consumer.py, line 425
[2019-10-01 11:17:01,552: WARNING/MainProcess] Traceback (most recent call last):
[2019-10-01 11:17:01,553: WARNING/MainProcess] File "c:\Python27\lib\logging\__init__.py", line 861, in emit
[2019-10-01 11:17:01,556: WARNING/MainProcess] msg = self.format(record)
[2019-10-01 11:17:01,559: WARNING/MainProcess] File "c:\Python27\lib\logging\__init__.py", line 734, in format
[2019-10-01 11:17:01,562: WARNING/MainProcess] return fmt.format(record)
[2019-10-01 11:17:01,562: WARNING/MainProcess] File "C:\Users\Marisha\AppData\Roaming\Python\Python27\site-packages\celery\utils\log.py", line 153, in format
[2019-10-01 11:17:01,565: WARNING/MainProcess] msg = logging.Formatter.format(self, record)
[2019-10-01 11:17:01,565: WARNING/MainProcess] File "c:\Python27\lib\logging\__init__.py", line 465, in format
[2019-10-01 11:17:01,569: WARNING/MainProcess] record.message = record.getMessage()
[2019-10-01 11:17:01,572: WARNING/MainProcess] File "c:\Python27\lib\logging\__init__.py", line 329, in getMessage
[2019-10-01 11:17:01,575: WARNING/MainProcess] msg = msg % self.args
[2019-10-01 11:17:01,576: WARNING/MainProcess] UnicodeDecodeError: 'ascii' codec can't decode byte 0xcf in position 14: ordinal not in range(128)
[2019-10-01 11:17:01,579: WARNING/MainProcess] Logged from file consumer.py, line 425
[2019-10-01 11:17:33,076: WARNING/MainProcess] Traceback (most recent call last):
[2019-10-01 11:17:33,078: WARNING/MainProcess] File "c:\Python27\lib\logging\__init__.py", line 861, in emit
[2019-10-01 11:17:33,081: WARNING/MainProcess] msg = self.format(record)
[2019-10-01 11:17:33,084: WARNING/MainProcess] File "c:\Python27\lib\logging\__init__.py", line 734, in format
[2019-10-01 11:17:33,086: WARNING/MainProcess] return fmt.format(record)
[2019-10-01 11:17:33,089: WARNING/MainProcess] File "C:\Users\Marisha\AppData\Roaming\Python\Python27\site-packages\celery\utils\log.py", line 153, in format
[2019-10-01 11:17:33,092: WARNING/MainProcess] msg = logging.Formatter.format(self, record)
[2019-10-01 11:17:33,095: WARNING/MainProcess] File "c:\Python27\lib\logging\__init__.py", line 465, in format
[2019-10-01 11:17:33,098: WARNING/MainProcess] record.message = record.getMessage()
[2019-10-01 11:17:33,101: WARNING/MainProcess] File "c:\Python27\lib\logging\__init__.py", line 329, in getMessage
[2019-10-01 11:17:33,105: WARNING/MainProcess] msg = msg % self.args
[2019-10-01 11:17:33,109: WARNING/MainProcess] UnicodeDecodeError: 'ascii' codec can't decode byte 0xcf in position 14: ordinal not in range(128)
[2019-10-01 11:17:33,115: WARNING/MainProcess] Logged from file consumer.py, line 425
[2019-10-01 11:18:06,244: WARNING/MainProcess] Traceback (most recent call last):
[2019-10-01 11:18:06,244: WARNING/MainProcess] File "c:\Python27\lib\logging\__init__.py", line 861, in emit
[2019-10-01 11:18:06,249: WARNING/MainProcess] msg = self.format(record)
[2019-10-01 11:18:06,253: WARNING/MainProcess] File "c:\Python27\lib\logging\__init__.py", line 734, in format
[2019-10-01 11:18:06,256: WARNING/MainProcess] return fmt.format(record)
[2019-10-01 11:18:06,263: WARNING/MainProcess] File "C:\Users\Marisha\AppData\Roaming\Python\Python27\site-packages\celery\utils\log.py", line 153, in format
[2019-10-01 11:18:06,267: WARNING/MainProcess] msg = logging.Formatter.format(self, record)
[2019-10-01 11:18:06,272: WARNING/MainProcess] File "c:\Python27\lib\logging\__init__.py", line 465, in format
[2019-10-01 11:18:06,276: WARNING/MainProcess] record.message = record.getMessage()
[2019-10-01 11:18:06,282: WARNING/MainProcess] File "c:\Python27\lib\logging\__init__.py", line 329, in getMessage
[2019-10-01 11:18:06,286: WARNING/MainProcess] msg = msg % self.args
[2019-10-01 11:18:06,290: WARNING/MainProcess] UnicodeDecodeError: 'ascii' codec can't decode byte 0xcf in position 14: ordinal not in range(128)
[2019-10-01 11:18:06,296: WARNING/MainProcess] Logged from file consumer.py, line 425
[2019-10-01 11:18:39,334: WARNING/MainProcess] Traceback (most recent call last):
[2019-10-01 11:18:39,335: WARNING/MainProcess] File "c:\Python27\lib\logging\__init__.py", line 861, in emit
[2019-10-01 11:18:39,338: WARNING/MainProcess] msg = self.format(record)
[2019-10-01 11:18:39,342: WARNING/MainProcess] File "c:\Python27\lib\logging\__init__.py", line 734, in format
[2019-10-01 11:18:39,345: WARNING/MainProcess] return fmt.format(record)
[2019-10-01 11:18:39,348: WARNING/MainProcess] File "C:\Users\Marisha\AppData\Roaming\Python\Python27\site-packages\celery\utils\log.py", line 153, in format
[2019-10-01 11:18:39,351: WARNING/MainProcess] msg = logging.Formatter.format(self, record)
[2019-10-01 11:18:39,354: WARNING/MainProcess] File "c:\Python27\lib\logging\__init__.py", line 465, in format
[2019-10-01 11:18:39,357: WARNING/MainProcess] record.message = record.getMessage()
[2019-10-01 11:18:39,359: WARNING/MainProcess] File "c:\Python27\lib\logging\__init__.py", line 329, in getMessage
[2019-10-01 11:18:39,364: WARNING/MainProcess] msg = msg % self.args
[2019-10-01 11:18:39,367: WARNING/MainProcess] UnicodeDecodeError: 'ascii' codec can't decode byte 0xcf in position 14: ordinal not in range(128)
[2019-10-01 11:18:39,369: WARNING/MainProcess] Logged from file consumer.py, line 425
[2019-10-01 11:19:12,427: WARNING/MainProcess] Traceback (most recent call last):
[2019-10-01 11:19:12,427: WARNING/MainProcess] File "c:\Python27\lib\logging\__init__.py", line 861, in emit
[2019-10-01 11:19:12,431: WARNING/MainProcess] msg = self.format(record)
[2019-10-01 11:19:12,434: WARNING/MainProcess] File "c:\Python27\lib\logging\__init__.py", line 734, in format
[2019-10-01 11:19:12,437: WARNING/MainProcess] return fmt.format(record)
[2019-10-01 11:19:12,441: WARNING/MainProcess] File "C:\Users\Marisha\AppData\Roaming\Python\Python27\site-packages\celery\utils\log.py", line 153, in format
[2019-10-01 11:19:12,446: WARNING/MainProcess] msg = logging.Formatter.format(self, record)
[2019-10-01 11:19:12,448: WARNING/MainProcess] File "c:\Python27\lib\logging\__init__.py", line 465, in format
[2019-10-01 11:19:12,451: WARNING/MainProcess] record.message = record.getMessage()
[2019-10-01 11:19:12,454: WARNING/MainProcess] File "c:\Python27\lib\logging\__init__.py", line 329, in getMessage
[2019-10-01 11:19:12,459: WARNING/MainProcess] msg = msg % self.args
[2019-10-01 11:19:12,461: WARNING/MainProcess] UnicodeDecodeError: 'ascii' codec can't decode byte 0xcf in position 14: ordinal not in range(128)
[2019-10-01 11:19:12,464: WARNING/MainProcess] Logged from file consumer.py, line 425
[2019-10-01 11:19:45,502: WARNING/MainProcess] Traceback (most recent call last):
[2019-10-01 11:19:45,503: WARNING/MainProcess] File "c:\Python27\lib\logging\__init__.py", line 861, in emit
[2019-10-01 11:19:45,506: WARNING/MainProcess] msg = self.format(record)
[2019-10-01 11:19:45,509: WARNING/MainProcess] File "c:\Python27\lib\logging\__init__.py", line 734, in format
[2019-10-01 11:19:45,519: WARNING/MainProcess] return fmt.format(record)
[2019-10-01 11:19:45,523: WARNING/MainProcess] File "C:\Users\Marisha\AppData\Roaming\Python\Python27\site-packages\celery\utils\log.py", line 153, in format
[2019-10-01 11:19:45,528: WARNING/MainProcess] msg = logging.Formatter.format(self, record)
[2019-10-01 11:19:45,532: WARNING/MainProcess] File "c:\Python27\lib\logging\__init__.py", line 465, in format
[2019-10-01 11:19:45,535: WARNING/MainProcess] record.message = record.getMessage()
[2019-10-01 11:19:45,538: WARNING/MainProcess] File "c:\Python27\lib\logging\__init__.py", line 329, in getMessage
[2019-10-01 11:19:45,540: WARNING/MainProcess] msg = msg % self.args
[2019-10-01 11:19:45,549: WARNING/MainProcess] UnicodeDecodeError: 'ascii' codec can't decode byte 0xcf in position 14: ordinal not in range(128)
[2019-10-01 11:19:45,552: WARNING/MainProcess] Logged from file consumer.py, line 425
[2019-10-01 11:20:18,595: WARNING/MainProcess] Traceback (most recent call last):
[2019-10-01 11:20:18,595: WARNING/MainProcess] File "c:\Python27\lib\logging\__init__.py", line 861, in emit
[2019-10-01 11:20:18,598: WARNING/MainProcess] msg = self.format(record)
[2019-10-01 11:20:18,601: WARNING/MainProcess] File "c:\Python27\lib\logging\__init__.py", line 734, in format
[2019-10-01 11:20:18,605: WARNING/MainProcess] return fmt.format(record)
[2019-10-01 11:20:18,608: WARNING/MainProcess] File "C:\Users\Marisha\AppData\Roaming\Python\Python27\site-packages\celery\utils\log.py", line 153, in format
[2019-10-01 11:20:18,611: WARNING/MainProcess] msg = logging.Formatter.format(self, record)
[2019-10-01 11:20:18,614: WARNING/MainProcess] File "c:\Python27\lib\logging\__init__.py", line 465, in format
[2019-10-01 11:20:18,617: WARNING/MainProcess] record.message = record.getMessage()
[2019-10-01 11:20:18,619: WARNING/MainProcess] File "c:\Python27\lib\logging\__init__.py", line 329, in getMessage
[2019-10-01 11:20:18,622: WARNING/MainProcess] msg = msg % self.args
[2019-10-01 11:20:18,627: WARNING/MainProcess] UnicodeDecodeError: 'ascii' codec can't decode byte 0xcf in position 14: ordinal not in range(128)
[2019-10-01 11:20:18,630: WARNING/MainProcess] Logged from file consumer.py, line 425
[2019-10-01 11:20:52,298: WARNING/MainProcess] Traceback (most recent call last):
[2019-10-01 11:20:52,299: WARNING/MainProcess] File "c:\Python27\lib\logging\__init__.py", line 861, in emit
[2019-10-01 11:20:52,301: WARNING/MainProcess] msg = self.format(record)
[2019-10-01 11:20:52,302: WARNING/MainProcess] File "c:\Python27\lib\logging\__init__.py", line 734, in format
[2019-10-01 11:20:52,305: WARNING/MainProcess] return fmt.format(record)
[2019-10-01 11:20:52,309: WARNING/MainProcess] File "C:\Users\Marisha\AppData\Roaming\Python\Python27\site-packages\celery\utils\log.py", line 153, in format
[2019-10-01 11:20:52,312: WARNING/MainProcess] msg = logging.Formatter.format(self, record)
[2019-10-01 11:20:52,315: WARNING/MainProcess] File "c:\Python27\lib\logging\__init__.py", line 465, in format
[2019-10-01 11:20:52,319: WARNING/MainProcess] record.message = record.getMessage()
[2019-10-01 11:20:52,322: WARNING/MainProcess] File "c:\Python27\lib\logging\__init__.py", line 329, in getMessage
[2019-10-01 11:20:52,325: WARNING/MainProcess] msg = msg % self.args
[2019-10-01 11:20:52,328: WARNING/MainProcess] UnicodeDecodeError: 'ascii' codec can't decode byte 0xcf in position 14: ordinal not in range(128)
[2019-10-01 11:20:52,331: WARNING/MainProcess] Logged from file consumer.py, line 425
[2019-10-01 11:21:26,696: WARNING/MainProcess] Traceback (most recent call last):
[2019-10-01 11:21:26,696: WARNING/MainProcess] File "c:\Python27\lib\logging\__init__.py", line 861, in emit
[2019-10-01 11:21:26,700: WARNING/MainProcess] msg = self.format(record)
[2019-10-01 11:21:26,703: WARNING/MainProcess] File "c:\Python27\lib\logging\__init__.py", line 734, in format
[2019-10-01 11:21:26,706: WARNING/MainProcess] return fmt.format(record)
[2019-10-01 11:21:26,709: WARNING/MainProcess] File "C:\Users\Marisha\AppData\Roaming\Python\Python27\site-packages\celery\utils\log.py", line 153, in format
[2019-10-01 11:21:26,711: WARNING/MainProcess] msg = logging.Formatter.format(self, record)
[2019-10-01 11:21:26,714: WARNING/MainProcess] File "c:\Python27\lib\logging\__init__.py", line 465, in format
[2019-10-01 11:21:26,717: WARNING/MainProcess] record.message = record.getMessage()
[2019-10-01 11:21:26,720: WARNING/MainProcess] File "c:\Python27\lib\logging\__init__.py", line 329, in getMessage
[2019-10-01 11:21:26,723: WARNING/MainProcess] msg = msg % self.args
[2019-10-01 11:21:26,726: WARNING/MainProcess] UnicodeDecodeError: 'ascii' codec can't decode byte 0xcf in position 14: ordinal not in range(128)
[2019-10-01 11:21:26,730: WARNING/MainProcess] Logged from file consumer.py, line 425
[2019-10-01 11:22:00,691: WARNING/MainProcess] Traceback (most recent call last):
[2019-10-01 11:22:00,693: WARNING/MainProcess] File "c:\Python27\lib\logging\__init__.py", line 861, in emit
[2019-10-01 11:22:00,696: WARNING/MainProcess] msg = self.format(record)
[2019-10-01 11:22:00,700: WARNING/MainProcess] File "c:\Python27\lib\logging\__init__.py", line 734, in format
[2019-10-01 11:22:00,704: WARNING/MainProcess] return fmt.format(record)
[2019-10-01 11:22:00,709: WARNING/MainProcess] File "C:\Users\Marisha\AppData\Roaming\Python\Python27\site-packages\celery\utils\log.py", line 153, in format
[2019-10-01 11:22:00,736: WARNING/MainProcess] msg = logging.Formatter.format(self, record)
[2019-10-01 11:22:00,740: WARNING/MainProcess] File "c:\Python27\lib\logging\__init__.py", line 465, in format
[2019-10-01 11:22:00,744: WARNING/MainProcess] record.message = record.getMessage()
[2019-10-01 11:22:00,749: WARNING/MainProcess] File "c:\Python27\lib\logging\__init__.py", line 329, in getMessage
[2019-10-01 11:22:00,753: WARNING/MainProcess] msg = msg % self.args
[2019-10-01 11:22:00,757: WARNING/MainProcess] UnicodeDecodeError: 'ascii' codec can't decode byte 0xcf in position 14: ordinal not in range(128)
[2019-10-01 11:22:00,765: WARNING/MainProcess] Logged from file consumer.py, line 425
[2019-10-01 19:58:10,573: INFO/MainProcess] beat: Starting...
[2019-10-01 20:01:01,467: INFO/MainProcess] Scheduler: Sending due task check_balance_and_writing_to_db (check_balance_and_writing_to_db)
[2019-10-01 20:18:29,668: INFO/MainProcess] beat: Starting...
